<?xml version="1.0" encoding="UTF-8"?>
<!-- Generated by org.testng.reporters.JUnitReportReporter -->
<testsuite hostname="GEVW59D07RA24FU" name="com.zs.auto.day06_1026.section2.login.LoginTest" tests="5" failures="0" timestamp="30 Oct 2019 16:37:13 GMT" time="9.279" errors="1">
  <testcase name="case_test" time="0.713" classname="com.zs.auto.day06_1026.section2.login.LoginTest"/>
  <testcase name="case_test" time="0.611" classname="com.zs.auto.day06_1026.section2.login.LoginTest">
    <error type="java.lang.AssertionError" message="expected [账号信息错误] but found []">
      <![CDATA[java.lang.AssertionError: expected [账号信息错误] but found []
	at org.testng.Assert.fail(Assert.java:94)
	at org.testng.Assert.failNotEquals(Assert.java:494)
	at org.testng.Assert.assertEquals(Assert.java:123)
	at org.testng.Assert.assertEquals(Assert.java:176)
	at org.testng.Assert.assertEquals(Assert.java:186)
	at com.zs.auto.day06_1026.section2.login.LoginTest.case_test(LoginTest.java:27)
	at sun.reflect.NativeMethodAccessorImpl.invoke0(Native Method)
	at sun.reflect.NativeMethodAccessorImpl.invoke(NativeMethodAccessorImpl.java:62)
	at sun.reflect.DelegatingMethodAccessorImpl.invoke(DelegatingMethodAccessorImpl.java:43)
	at java.lang.reflect.Method.invoke(Method.java:498)
	at org.testng.internal.MethodInvocationHelper.invokeMethod(MethodInvocationHelper.java:84)
	at org.testng.internal.Invoker.invokeMethod(Invoker.java:714)
	at org.testng.internal.Invoker.invokeTestMethod(Invoker.java:901)
	at org.testng.internal.Invoker.invokeTestMethods(Invoker.java:1231)
	at org.testng.internal.TestMethodWorker.invokeTestMethods(TestMethodWorker.java:127)
	at org.testng.internal.TestMethodWorker.run(TestMethodWorker.java:111)
	at org.testng.TestRunner.privateRun(TestRunner.java:767)
	at org.testng.TestRunner.run(TestRunner.java:617)
	at org.testng.SuiteRunner.runTest(SuiteRunner.java:348)
	at org.testng.SuiteRunner.runSequentially(SuiteRunner.java:343)
	at org.testng.SuiteRunner.privateRun(SuiteRunner.java:305)
	at org.testng.SuiteRunner.run(SuiteRunner.java:254)
	at org.testng.SuiteRunnerWorker.runSuite(SuiteRunnerWorker.java:52)
	at org.testng.SuiteRunnerWorker.run(SuiteRunnerWorker.java:86)
	at org.testng.TestNG.runSuitesSequentially(TestNG.java:1224)
	at org.testng.TestNG.runSuitesLocally(TestNG.java:1149)
	at org.testng.TestNG.run(TestNG.java:1057)
	at org.testng.remote.AbstractRemoteTestNG.run(AbstractRemoteTestNG.java:114)
	at org.testng.remote.RemoteTestNG.initAndRun(RemoteTestNG.java:251)
	at org.testng.remote.RemoteTestNG.main(RemoteTestNG.java:77)
]]>
    </error>
  </testcase> <!-- case_test -->
  <testcase name="case_test" time="0.720" classname="com.zs.auto.day06_1026.section2.login.LoginTest"/>
  <testcase name="case_test" time="6.774" classname="com.zs.auto.day06_1026.section2.login.LoginTest"/>
  <testcase name="case_test" time="0.461" classname="com.zs.auto.day06_1026.section2.login.LoginTest"/>
</testsuite> <!-- com.zs.auto.day06_1026.section2.login.LoginTest -->
